[2020-12-21T20:05:12Z] DEBUG    - Logging set up successfully
[2020-12-21T20:05:12Z] DEBUG    - Running generate: Namespace(version=False, subparser_name='generate', command=<function generate at 0x119615af0>, verbose=0)
[2020-12-21T20:05:12Z] DEBUG    - Root directory: /Volumes/workplace/aws-cloudformation-resource-providers-cost-explorer
[2020-12-21T20:05:12Z] DEBUG    - Loading project file '/Volumes/workplace/aws-cloudformation-resource-providers-cost-explorer/.rpdk-config'
[2020-12-21T20:05:12Z] DEBUG    - Project file not found. Have you run 'init'?
Traceback (most recent call last):
  File "/usr/local/lib/python3.9/site-packages/rpdk/core/project.py", line 411, in load
    self.load_settings()
  File "/usr/local/lib/python3.9/site-packages/rpdk/core/project.py", line 188, in load_settings
    with self.settings_path.open("r", encoding="utf-8") as f:
  File "/usr/local/Cellar/python@3.9/3.9.0_1/Frameworks/Python.framework/Versions/3.9/lib/python3.9/pathlib.py", line 1241, in open
    return io.open(self, mode, buffering, encoding, errors, newline,
  File "/usr/local/Cellar/python@3.9/3.9.0_1/Frameworks/Python.framework/Versions/3.9/lib/python3.9/pathlib.py", line 1109, in _opener
    return self._accessor.open(self, flags, mode)
FileNotFoundError: [Errno 2] No such file or directory: '/Volumes/workplace/aws-cloudformation-resource-providers-cost-explorer/.rpdk-config'
[2020-12-21T20:05:12Z] DEBUG    - Caught exit recommendation
Traceback (most recent call last):
  File "/usr/local/lib/python3.9/site-packages/rpdk/core/project.py", line 411, in load
    self.load_settings()
  File "/usr/local/lib/python3.9/site-packages/rpdk/core/project.py", line 188, in load_settings
    with self.settings_path.open("r", encoding="utf-8") as f:
  File "/usr/local/Cellar/python@3.9/3.9.0_1/Frameworks/Python.framework/Versions/3.9/lib/python3.9/pathlib.py", line 1241, in open
    return io.open(self, mode, buffering, encoding, errors, newline,
  File "/usr/local/Cellar/python@3.9/3.9.0_1/Frameworks/Python.framework/Versions/3.9/lib/python3.9/pathlib.py", line 1109, in _opener
    return self._accessor.open(self, flags, mode)
FileNotFoundError: [Errno 2] No such file or directory: '/Volumes/workplace/aws-cloudformation-resource-providers-cost-explorer/.rpdk-config'

The above exception was the direct cause of the following exception:

Traceback (most recent call last):
  File "/usr/local/lib/python3.9/site-packages/rpdk/core/cli.py", line 100, in main
    args.command(args)
  File "/usr/local/lib/python3.9/site-packages/rpdk/core/generate.py", line 14, in generate
    project.load()
  File "/usr/local/lib/python3.9/site-packages/rpdk/core/project.py", line 413, in load
    self._raise_invalid_project(
  File "/usr/local/lib/python3.9/site-packages/rpdk/core/project.py", line 183, in _raise_invalid_project
    raise InvalidProjectError(msg) from e
rpdk.core.exceptions.InvalidProjectError: Project file not found. Have you run 'init'?
[2020-12-21T20:05:12Z] CRITICAL - Project file not found. Have you run 'init'?
